<?xml version="1.0"?>
<robot name="dyn_ef_robot" xmlns:xacro="http://www.ros.org/wiki/xacro">

  <xacro:property name="height" value="2.0" />
  <!-- <xacro:property name="pi" value="3.141592654" /> -->
  <xacro:macro name="default_inertial" params="mass">
    <inertial>
      <mass value="${mass}" />
      <inertia ixx="1.0" ixy="0.0" ixz="0.0" iyy="1.0" iyz="0.0" izz="1.0" />
    </inertial>
  </xacro:macro>

  <material name="blue">
    <color rgba="0 0 0.8 1"/>
  </material>

  <link name="world"/>

  <joint name="fixy" type="fixed">
    <parent link="world"/>
    <child link="base_link"/>
  </joint>

  <link name="base_link">
    <visual>
      <origin xyz="0 0 0.09" rpy="${pi/2.0} 0 0" />
      <geometry>
        <mesh filename="package://dynamic_end_effector/meshes/h54-200-s500-r.stl" scale="0.001 0.001 0.001"/>
      </geometry>
    </visual>
    <collision>
      <origin xyz="0 0 0.09" rpy="${pi/2.0} 0 0" />
      <geometry>
        <mesh filename="package://dynamic_end_effector/meshes/h54-200-s500-r.stl" scale="0.001 0.001 0.001"/>
      </geometry>
    </collision>
    <xacro:default_inertial mass="0.8"/>
  </link>

  <joint name="base_link_to_base_yaw_link_joint" type="continuous">
    <parent link="base_link"/>
    <child link="base_yaw_link"/>
    <origin xyz="0 0 0.126"/>
    <axis xyz="0 0 1"/>
  </joint>

  <link name="base_yaw_link">
    <visual>
      <origin xyz="0 0 0" rpy="0 0 0" />
      <geometry>
        <mesh filename="package://dynamic_end_effector/meshes/assembly_base.stl" scale="0.001 0.001 0.001"/>
      </geometry>
    </visual>
    <collision>
      <origin xyz="0 0 0" rpy="0 0 0" />
      <geometry>
        <mesh filename="package://dynamic_end_effector/meshes/assembly_base.stl" scale="0.001 0.001 0.001"/>
      </geometry>
    </collision>
    <inertial>
      <mass value="10"/>
      <inertia ixx="0.01" ixy="0.01" ixz="0.01" iyy="0.01" iyz="0.01" izz="0.01"/>
    </inertial>
    <xacro:default_inertial mass="0.8"/>
  </link>

  <joint name="base_yaw_link_to_first_link_joint" type="revolute">
    <parent link="base_yaw_link"/>
    <child link="first_link"/>
    <origin xyz="0 0 0.042"/>
    <axis xyz="1 0 0"/>
    <dynamics damping="1.0" friction="5.0"/>
    <limit upper="2.0" lower="-2.0" effort="45" velocity="1"/>
  </joint>

  <link name="first_link">
    <visual>
      <origin xyz="0 0 0" rpy="${pi/2.0} 0 0" />
      <geometry>
        <mesh filename="package://dynamic_end_effector/meshes/assembly_linkOne.stl" scale="0.001 0.001 0.001"/>
      </geometry>
    </visual>
    <collision>
      <origin xyz="0 0 0" rpy="${pi/2.0} 0 0" />
      <geometry>
        <mesh filename="package://dynamic_end_effector/meshes/assembly_linkOne.stl" scale="0.001 0.001 0.001"/>
      </geometry>
    </collision>
    <xacro:default_inertial mass="2"/>
  </link>

  <joint name="first_link_to_second_link_joint" type="continuous">
    <parent link="first_link"/>
    <child link="second_link"/>
    <origin xyz="0 0 0.806"/>
    <axis xyz="1 0 0"/>
    <dynamics damping="1.0" friction="5.0"/>
  </joint>

  <link name="second_link">
    <visual>
      <origin xyz="-0.033 0 0" rpy="${pi/2.0} -${pi/2.0} 0" />
      <geometry>
        <mesh filename="package://dynamic_end_effector/meshes/assembly_linkTwo.stl" scale="0.001 0.001 0.001"/>
      </geometry>
    </visual>
    <collision>
      <origin xyz="-0.033 0 0" rpy="${pi/2.0} -${pi/2.0} 0" />
      <geometry>
        <mesh filename="package://dynamic_end_effector/meshes/assembly_linkTwo.stl" scale="0.001 0.001 0.001"/>
      </geometry>
    </collision>
    <xacro:default_inertial mass="1"/>
  </link>

  <joint name="second_link_to_third_link_joint" type="continuous">
    <parent link="second_link"/>
    <child link="third_link"/>
    <origin xyz="-0.06 0 0.61555"/>
    <axis xyz="0 0 1"/>
    <dynamics damping="1.0" friction="5.0"/>
  </joint>

  <link name="third_link">
    <visual>
      <origin xyz="0 0 0" rpy="0 0 0" />
      <geometry>
        <mesh filename="package://dynamic_end_effector/meshes/assembly_linkThree.stl" scale="0.001 0.001 0.001"/>
      </geometry>
    </visual>
    <collision>
      <origin xyz="0 0 0" rpy="0 0 0" />
      <geometry>
        <mesh filename="package://dynamic_end_effector/meshes/assembly_linkThree.stl" scale="0.001 0.001 0.001"/>
      </geometry>
    </collision>
    <xacro:default_inertial mass="0.1"/>
  </link>

  <joint name="third_link_to_fourth_link_joint" type="continuous">
    <parent link="third_link"/>
    <child link="fourth_link"/>
    <origin xyz="-0.025262 0 0.0383"/>
    <axis xyz="1 0 0"/>
    <dynamics damping="1.0" friction="5.0"/>
  </joint>

  <link name="fourth_link">
    <visual>
      <origin xyz="0 0 0" rpy="${pi/2.0} 0 ${pi/2.0}" />
      <!-- <origin xyz="0 0 0" rpy="0 0 0"/> -->
      <geometry>
        <mesh filename="package://dynamic_end_effector/meshes/assembly_linkFour.stl" scale="0.001 0.001 0.001"/>
      </geometry>
    </visual>
    <collision>
      <origin xyz="0 0 0" rpy="${pi/2.0} 0 ${pi/2.0}" />
      <!-- <origin xyz="0 0 0" rpy="0 0 0"/> -->
      <geometry>
        <mesh filename="package://dynamic_end_effector/meshes/assembly_linkFour.stl" scale="0.001 0.001 0.001"/>
      </geometry>
    </collision>
    <xacro:default_inertial mass="0.3"/>
  </link>

  <joint name="fourth_link_to_fifth_link_joint" type="continuous">
    <parent link="fourth_link"/>
    <child link="fifth_link"/>
    <origin xyz="0.0278 0 0.09375"/>
    <axis xyz="0 0 1"/>
    <dynamics damping="1.0" friction="5.0"/>
  </joint>

  <link name="fifth_link">
    <visual>
      <origin xyz="0 0 0" rpy="${pi/2.0} 0 0" />
      <!-- <origin xyz="0 0 0" rpy="0 0 0"/> -->
      <geometry>
        <mesh filename="package://dynamic_end_effector/meshes/assembly_linkFive.stl" scale="0.001 0.001 0.001"/>
      </geometry>
    </visual>
    <collision>
      <origin xyz="0 0 0" rpy="${pi/2.0} 0 0" />
      <!-- <origin xyz="0 0 0" rpy="0 0 0"/> -->
      <geometry>
        <mesh filename="package://dynamic_end_effector/meshes/assembly_linkFive.stl" scale="0.001 0.001 0.001"/>
      </geometry>
    </collision>
    <xacro:default_inertial mass="0.01"/>
  </link>



</robot>