<?xml version="1.0"?>
<robot
  name="dyn_ef_sw" xmlns:xacro="http://www.ros.org/wiki/xacro">
  <link
    name="base_link">
    <inertial>
      <origin
        xyz="-0.12731 0.59363 0.060479"
        rpy="0 0 0" />
      <mass
        value="0.33438" />
      <inertia
        ixx="0.00049255"
        ixy="-1.1863E-09"
        ixz="-1.2741E-11"
        iyy="0.00049234"
        iyz="-2.2616E-09"
        izz="0.00014805" />
    </inertial>
    <visual>
      <origin
        xyz="0 0 0"
        rpy="0 0 0" />
      <geometry>
        <mesh
          filename="package://dyn_ef_sw/meshes/base_link.STL" />
      </geometry>
      <material
        name="">
        <color
          rgba="0.2 0.2 1 1" />
      </material>
    </visual>
    <collision>
      <origin
        xyz="0 0 0"
        rpy="0 0 0" />
      <geometry>
        <mesh
          filename="package://dyn_ef_sw/meshes/base_link.STL" />
      </geometry>
    </collision>
  </link>
  <link
    name="base_frame">
    <inertial>
      <origin
        xyz="0.025543 -0.006754 -5.5511E-17"
        rpy="0 0 0" />
      <mass
        value="0.086957" />
      <inertia
        ixx="0.00033591"
        ixy="-1.1984E-05"
        ixz="-1.0164E-20"
        iyy="8.9913E-05"
        iyz="1.6263E-19"
        izz="0.0003769" />
    </inertial>
    <visual>
      <origin
        xyz="0 0 0"
        rpy="0 0 0" />
      <geometry>
        <mesh
          filename="package://dyn_ef_sw/meshes/base_frame.STL" />
      </geometry>
      <material
        name="">
        <color
          rgba="0.1 0.1 1 1" />
      </material>
    </visual>
    <collision>
      <origin
        xyz="0 0 0"
        rpy="0 0 0" />
      <geometry>
        <mesh
          filename="package://dyn_ef_sw/meshes/base_frame.STL" />
      </geometry>
    </collision>
  </link>

  <joint
    name="joint_base_frame"
    type="revolute">
    <origin
      xyz="0 0 0.126"
      rpy="0 ${-pi/2} 0"/>
      <!-- xyz="-0.13396 -0.126 0.58616"
      rpy="-2.2983 -6.123E-17 -1.5708" /> -->
    <parent
      link="base_link" />
    <child
      link="base_frame" />
    <axis
      xyz="1 0 0" />
    <limit
      upper="${pi}"
      lower="${-pi}"
      effort="0"
      velocity="0" />
  </joint>

  <link
    name="first_long_link">
    <inertial>
      <origin
        xyz="0.22258 -0.0016427 0.01177"
        rpy="0 0 0" />
      <mass
        value="1.0287" />
      <inertia
        ixx="0.0018244"
        ixy="6.0124E-05"
        ixz="-0.0025341"
        iyy="0.040599"
        iyz="1.5599E-05"
        izz="0.041275" />
    </inertial>
    <visual>
      <origin
        xyz="0 0 0"
        rpy="0 0 0" />
      <geometry>
        <mesh
          filename="package://dyn_ef_sw/meshes/first_long_link.STL" />
      </geometry>
      <material
        name="">
        <color
          rgba="0.75294 0.75294 0.75294 1" />
      </material>
    </visual>
    <collision>
      <origin
        xyz="0 0 0"
        rpy="0 0 0" />
      <geometry>
        <mesh
          filename="package://dyn_ef_sw/meshes/first_long_link.STL" />
      </geometry>
    </collision>
  </link>
  <joint
    name="joint_first_long_link"
    type="revolute">
    <origin
      xyz="0.068 -0.01 0"
      rpy="3.1416 -1.3907 1.3947E-14" />
    <parent
      link="base_frame" />
    <child
      link="first_long_link" />
    <axis
      xyz="0 1 0" />
    <limit
      upper="${pi}"
      lower="${-pi}"
      effort="0"
      velocity="0" />
  </joint>
  <link
    name="second_long_link">
    <inertial>
      <origin
        xyz="0.030056 -0.0043924 0.26307"
        rpy="0 0 0" />
      <mass
        value="0.61816" />
      <inertia
        ixx="0.011142"
        ixy="1.9988E-06"
        ixz="-0.00015305"
        iyy="0.010867"
        iyz="1.7495E-05"
        izz="0.0007011" />
    </inertial>
    <visual>
      <origin
        xyz="0 0 0"
        rpy="0 0 0" />
      <geometry>
        <mesh
          filename="package://dyn_ef_sw/meshes/second_long_link.STL" />
      </geometry>
      <material
        name="">
        <color
          rgba="0.75294 0.75294 0.75294 1" />
      </material>
    </visual>
    <collision>
      <origin
        xyz="0 0 0"
        rpy="0 0 0" />
      <geometry>
        <mesh
          filename="package://dyn_ef_sw/meshes/second_long_link.STL" />
      </geometry>
    </collision>
  </link>
  <joint
    name="joint_second_long_link"
    type="revolute">
    <origin
      xyz="0.43061 0 0.033838"
      rpy="-4.2772E-15 0.99042 -1.0327E-15" />
    <parent
      link="first_long_link" />
    <child
      link="second_long_link" />
    <axis
      xyz="0 1 0" />
    <limit
      upper="${pi}"
      lower="${-pi}"
      effort="0"
      velocity="0" />
  </joint>
  <link
    name="frame_hand">
    <inertial>
      <origin
        xyz="-1.1102E-16 0.025874 -0.00068401"
        rpy="0 0 0" />
      <mass
        value="0.020014" />
      <inertia
        ixx="1.6966E-05"
        ixy="2.5623E-20"
        ixz="-2.827E-20"
        iyy="1.487E-05"
        iyz="2.7315E-07"
        izz="8.7545E-06" />
    </inertial>
    <visual>
      <origin
        xyz="0 0 0"
        rpy="0 0 0" />
      <geometry>
        <mesh
          filename="package://dyn_ef_sw/meshes/frame_hand.STL" />
      </geometry>
      <material
        name="">
        <color
          rgba="0.79216 0.81961 0.93333 1" />
      </material>
    </visual>
    <collision>
      <origin
        xyz="0 0 0"
        rpy="0 0 0" />
      <geometry>
        <mesh
          filename="package://dyn_ef_sw/meshes/frame_hand.STL" />
      </geometry>
    </collision>
  </link>
  <joint
    name="joint_frame_hand"
    type="revolute">
    <origin
      xyz="0.031 -0.0045 0.41117"
      rpy="1.5708 -5.2736E-16 -1.3014" />
    <parent
      link="second_long_link" />
    <child
      link="frame_hand" />
    <axis
      xyz="0 1 0" />
    <limit
      upper="${pi}"
      lower="${-pi}"
      effort="0"
      velocity="0" />
  </joint>
  <link
    name="hand">
    <inertial>
      <origin
        xyz="-0.0066548 -0.051172 -0.001503"
        rpy="0 0 0" />
      <mass
        value="0.2073" />
      <inertia
        ixx="0.00032345"
        ixy="-4.7303E-05"
        ixz="-4.4164E-08"
        iyy="8.7039E-05"
        iyz="-4.7358E-08"
        izz="0.00036467" />
    </inertial>
    <visual>
      <origin
        xyz="0 0 0"
        rpy="0 0 0" />
      <geometry>
        <mesh
          filename="package://dyn_ef_sw/meshes/hand.STL" />
      </geometry>
      <material
        name="">
        <color
          rgba="0.75294 0.75294 0.75294 1" />
      </material>
    </visual>
    <collision>
      <origin
        xyz="0 0 0"
        rpy="0 0 0" />
      <geometry>
        <mesh
          filename="package://dyn_ef_sw/meshes/hand.STL" />
      </geometry>
    </collision>
  </link>
  <joint
    name="joint_hand"
    type="revolute">
    <origin
      xyz="0 0.05 0"
      rpy="2.7711 1.5708 0" />
    <parent
      link="frame_hand" />
    <child
      link="hand" />
    <axis
      xyz="-1 0 0" />
    <limit
      upper="${pi}"
      lower="${-pi}"
      effort="0"
      velocity="0" />
  </joint>
</robot>